[2024-02-05T21:39:50.759-0500] {taskinstance.py:1956} INFO - Dependencies all met for dep_context=non-requeueable deps ti=<TaskInstance: etl_pipeline.etl_task scheduled__2024-02-05T00:00:00+00:00 [queued]>
[2024-02-05T21:39:50.765-0500] {taskinstance.py:1956} INFO - Dependencies all met for dep_context=requeueable deps ti=<TaskInstance: etl_pipeline.etl_task scheduled__2024-02-05T00:00:00+00:00 [queued]>
[2024-02-05T21:39:50.765-0500] {taskinstance.py:2170} INFO - Starting attempt 1 of 1
[2024-02-05T21:39:50.771-0500] {taskinstance.py:2191} INFO - Executing <Task(PythonOperator): etl_task> on 2024-02-05 00:00:00+00:00
[2024-02-05T21:39:50.772-0500] {standard_task_runner.py:60} INFO - Started process 13947 to run task
[2024-02-05T21:39:50.773-0500] {clientserver.py:543} INFO - Closing down clientserver connection
[2024-02-05T21:39:50.776-0500] {standard_task_runner.py:87} INFO - Running: ['airflow', 'tasks', 'run', 'etl_pipeline', 'etl_task', 'scheduled__2024-02-05T00:00:00+00:00', '--job-id', '2', '--raw', '--subdir', 'DAGS_FOLDER/dags.py', '--cfg-path', '/var/folders/1_/ys48lvmx1ks83w1qrm7syj0h0000gn/T/tmpenlvkg5s']
[2024-02-05T21:39:50.777-0500] {standard_task_runner.py:88} INFO - Job 2: Subtask etl_task
[2024-02-05T21:39:50.824-0500] {task_command.py:423} INFO - Running <TaskInstance: etl_pipeline.etl_task scheduled__2024-02-05T00:00:00+00:00 [running]> on host ***s-mbp
[2024-02-05T21:39:50.864-0500] {clientserver.py:505} INFO - Error while sending or receiving.
Traceback (most recent call last):
  File "/Users/ayushi/PycharmProjects/etl/venv/lib/python3.11/site-packages/py4j/clientserver.py", line 503, in send_command
    self.socket.sendall(command.encode("utf-8"))
BrokenPipeError: [Errno 32] Broken pipe
[2024-02-05T21:39:50.865-0500] {clientserver.py:543} INFO - Closing down clientserver connection
[2024-02-05T21:39:50.866-0500] {java_gateway.py:1052} INFO - Exception while sending command.
Traceback (most recent call last):
  File "/Users/ayushi/PycharmProjects/etl/venv/lib/python3.11/site-packages/py4j/clientserver.py", line 503, in send_command
    self.socket.sendall(command.encode("utf-8"))
BrokenPipeError: [Errno 32] Broken pipe

During handling of the above exception, another exception occurred:

Traceback (most recent call last):
  File "/Users/ayushi/PycharmProjects/etl/venv/lib/python3.11/site-packages/py4j/java_gateway.py", line 1038, in send_command
    response = connection.send_command(command)
               ^^^^^^^^^^^^^^^^^^^^^^^^^^^^^^^^
  File "/Users/ayushi/PycharmProjects/etl/venv/lib/python3.11/site-packages/py4j/clientserver.py", line 506, in send_command
    raise Py4JNetworkError(
py4j.protocol.Py4JNetworkError: Error while sending
[2024-02-05T21:39:50.867-0500] {clientserver.py:543} INFO - Closing down clientserver connection
[2024-02-05T21:39:50.882-0500] {taskinstance.py:2480} INFO - Exporting env vars: AIRFLOW_CTX_DAG_EMAIL='info@example.com' AIRFLOW_CTX_DAG_OWNER='***' AIRFLOW_CTX_DAG_ID='etl_pipeline' AIRFLOW_CTX_TASK_ID='etl_task' AIRFLOW_CTX_EXECUTION_DATE='2024-02-05T00:00:00+00:00' AIRFLOW_CTX_TRY_NUMBER='1' AIRFLOW_CTX_DAG_RUN_ID='scheduled__2024-02-05T00:00:00+00:00'
[2024-02-05T21:39:51.057-0500] {python.py:201} INFO - Done. Returned value was: None
[2024-02-05T21:39:51.065-0500] {taskinstance.py:1138} INFO - Marking task as SUCCESS. dag_id=etl_pipeline, task_id=etl_task, execution_date=20240205T000000, start_date=20240206T023950, end_date=20240206T023951
[2024-02-05T21:39:51.083-0500] {local_task_job_runner.py:234} INFO - Task exited with return code 0
[2024-02-05T21:39:51.097-0500] {taskinstance.py:3280} INFO - 0 downstream tasks scheduled from follow-on schedule check
