Traceback (most recent call last):
  File "/Users/ayushi/PycharmProjects/etl/venv/lib/python3.11/site-packages/psutil/_psosx.py", line 352, in wrapper
    return fun(self, *args, **kwargs)
           ^^^^^^^^^^^^^^^^^^^^^^^^^^
  File "/Users/ayushi/PycharmProjects/etl/venv/lib/python3.11/site-packages/psutil/_common.py", line 497, in wrapper
    raise raise_from(err, None)
          ^^^^^^^^^^^^^^^^^^^^^
  File "<string>", line 3, in raise_from
  File "/Users/ayushi/PycharmProjects/etl/venv/lib/python3.11/site-packages/psutil/_common.py", line 495, in wrapper
    return fun(self)
           ^^^^^^^^^
  File "/Users/ayushi/PycharmProjects/etl/venv/lib/python3.11/site-packages/psutil/_psosx.py", line 378, in _get_kinfo_proc
    ret = cext.proc_kinfo_oneshot(self.pid)
          ^^^^^^^^^^^^^^^^^^^^^^^^^^^^^^^^^
ProcessLookupError: [Errno 3] assume no such process (originated from sysctl(kinfo_proc), len == 0)

During handling of the above exception, another exception occurred:

Traceback (most recent call last):
  File "/Users/ayushi/PycharmProjects/etl/venv/lib/python3.11/site-packages/psutil/__init__.py", line 359, in _init
    self.create_time()
  File "/Users/ayushi/PycharmProjects/etl/venv/lib/python3.11/site-packages/psutil/__init__.py", line 752, in create_time
    self._create_time = self._proc.create_time()
                        ^^^^^^^^^^^^^^^^^^^^^^^^
  File "/Users/ayushi/PycharmProjects/etl/venv/lib/python3.11/site-packages/psutil/_psosx.py", line 352, in wrapper
    return fun(self, *args, **kwargs)
           ^^^^^^^^^^^^^^^^^^^^^^^^^^
  File "/Users/ayushi/PycharmProjects/etl/venv/lib/python3.11/site-packages/psutil/_psosx.py", line 480, in create_time
    return self._get_kinfo_proc()[kinfo_proc_map['ctime']]
           ^^^^^^^^^^^^^^^^^^^^^^
  File "/Users/ayushi/PycharmProjects/etl/venv/lib/python3.11/site-packages/psutil/_psosx.py", line 357, in wrapper
    raise NoSuchProcess(self.pid, self._name)
psutil.NoSuchProcess: process no longer exists (pid=13358)

During handling of the above exception, another exception occurred:

Traceback (most recent call last):
  File "/Users/ayushi/PycharmProjects/etl/venv/bin/airflow", line 8, in <module>
    sys.exit(main())
             ^^^^^^
  File "/Users/ayushi/PycharmProjects/etl/venv/lib/python3.11/site-packages/airflow/__main__.py", line 57, in main
    args.func(args)
  File "/Users/ayushi/PycharmProjects/etl/venv/lib/python3.11/site-packages/airflow/cli/cli_config.py", line 49, in command
    return func(*args, **kwargs)
           ^^^^^^^^^^^^^^^^^^^^^
  File "/Users/ayushi/PycharmProjects/etl/venv/lib/python3.11/site-packages/airflow/utils/cli.py", line 114, in wrapper
    return f(*args, **kwargs)
           ^^^^^^^^^^^^^^^^^^
  File "/Users/ayushi/PycharmProjects/etl/venv/lib/python3.11/site-packages/airflow/utils/providers_configuration_loader.py", line 55, in wrapped_function
    return func(*args, **kwargs)
           ^^^^^^^^^^^^^^^^^^^^^
  File "/Users/ayushi/PycharmProjects/etl/venv/lib/python3.11/site-packages/airflow/cli/commands/webserver_command.py", line 484, in webserver
    run_command_with_daemon_option(
  File "/Users/ayushi/PycharmProjects/etl/venv/lib/python3.11/site-packages/airflow/cli/commands/daemon_utils.py", line 81, in run_command_with_daemon_option
    callback()
  File "/Users/ayushi/PycharmProjects/etl/venv/lib/python3.11/site-packages/airflow/cli/commands/webserver_command.py", line 487, in <lambda>
    callback=lambda: start_and_monitor_gunicorn(args),
                     ^^^^^^^^^^^^^^^^^^^^^^^^^^^^^^^^
  File "/Users/ayushi/PycharmProjects/etl/venv/lib/python3.11/site-packages/airflow/cli/commands/webserver_command.py", line 471, in start_and_monitor_gunicorn
    monitor_gunicorn(gunicorn_master_proc)
  File "/Users/ayushi/PycharmProjects/etl/venv/lib/python3.11/site-packages/airflow/cli/commands/webserver_command.py", line 456, in monitor_gunicorn
    ).start()
      ^^^^^^^
  File "/Users/ayushi/PycharmProjects/etl/venv/lib/python3.11/site-packages/airflow/cli/commands/webserver_command.py", line 217, in start
    self._check_workers()
  File "/Users/ayushi/PycharmProjects/etl/venv/lib/python3.11/site-packages/airflow/cli/commands/webserver_command.py", line 263, in _check_workers
    num_workers_running = self._get_num_workers_running()
                          ^^^^^^^^^^^^^^^^^^^^^^^^^^^^^^^
  File "/Users/ayushi/PycharmProjects/etl/venv/lib/python3.11/site-packages/airflow/cli/commands/webserver_command.py", line 150, in _get_num_workers_running
    workers = psutil.Process(self.gunicorn_master_proc.pid).children()
              ^^^^^^^^^^^^^^^^^^^^^^^^^^^^^^^^^^^^^^^^^^^^^
  File "/Users/ayushi/PycharmProjects/etl/venv/lib/python3.11/site-packages/psutil/__init__.py", line 323, in __init__
    self._init(pid)
  File "/Users/ayushi/PycharmProjects/etl/venv/lib/python3.11/site-packages/psutil/__init__.py", line 372, in _init
    raise NoSuchProcess(pid, msg=msg)
psutil.NoSuchProcess: process PID not found (pid=13358)
